PS C:\Users\W0024618\Desktop\ai-employee-security\src> python train.py
Traceback (most recent call last):
  File "C:\Users\W0024618\Desktop\ai-employee-security\src\train.py", line 188, in <module>
    build_and_save_model()
    ~~~~~~~~~~~~~~~~~~~~^^
  File "C:\Users\W0024618\Desktop\ai-employee-security\src\train.py", line 124, in build_and_save_model
    df_labeled = apply_all_labelers(df)
  File "C:\Users\W0024618\Desktop\ai-employee-security\src\train.py", line 39, in apply_all_labelers
    df = label_anomaly(df)
  File "C:\Users\W0024618\Desktop\ai-employee-security\src\labelers.py", line 25, in label_anomaly
    df["swipe_count_rolling"] = (
    ~~^^^^^^^^^^^^^^^^^^^^^^^
  File "C:\Users\W0024618\Desktop\ai-employee-security\venv\Lib\site-packages\pandas\core\frame.py", line 4311, in __setitem__
    self._set_item(key, value)
    ~~~~~~~~~~~~~~^^^^^^^^^^^^
  File "C:\Users\W0024618\Desktop\ai-employee-security\venv\Lib\site-packages\pandas\core\frame.py", line 4524, in _set_item
    value, refs = self._sanitize_column(value)
                  ~~~~~~~~~~~~~~~~~~~~~^^^^^^^
  File "C:\Users\W0024618\Desktop\ai-employee-security\venv\Lib\site-packages\pandas\core\frame.py", line 5263, in _sanitize_column
    return _reindex_for_setitem(value, self.index)
  File "C:\Users\W0024618\Desktop\ai-employee-security\venv\Lib\site-packages\pandas\core\frame.py", line 12692, in _reindex_for_setitem
    raise err
  File "C:\Users\W0024618\Desktop\ai-employee-security\venv\Lib\site-packages\pandas\core\frame.py", line 12687, in _reindex_for_setitem
    reindexed_value = value.reindex(index)._values
                      ~~~~~~~~~~~~~^^^^^^^
  File "C:\Users\W0024618\Desktop\ai-employee-security\venv\Lib\site-packages\pandas\core\series.py", line 5153, in reindex
    return super().reindex(
           ~~~~~~~~~~~~~~~^
        index=index,
        ^^^^^^^^^^^^
    ...<5 lines>...
        tolerance=tolerance,
        ^^^^^^^^^^^^^^^^^^^^
    )
    ^
  File "C:\Users\W0024618\Desktop\ai-employee-security\venv\Lib\site-packages\pandas\core\generic.py", line 5610, in reindex
    return self._reindex_axes(
           ~~~~~~~~~~~~~~~~~~^
        axes, level, limit, tolerance, method, fill_value, copy
        ^^^^^^^^^^^^^^^^^^^^^^^^^^^^^^^^^^^^^^^^^^^^^^^^^^^^^^^
    ).__finalize__(self, method="reindex")
    ^
  File "C:\Users\W0024618\Desktop\ai-employee-security\venv\Lib\site-packages\pandas\core\generic.py", line 5633, in _reindex_axes
    new_index, indexer = ax.reindex(
                         ~~~~~~~~~~^
        labels, level=level, limit=limit, tolerance=tolerance, method=method
        ^^^^^^^^^^^^^^^^^^^^^^^^^^^^^^^^^^^^^^^^^^^^^^^^^^^^^^^^^^^^^^^^^^^^
    )
    ^
  File "C:\Users\W0024618\Desktop\ai-employee-security\venv\Lib\site-packages\pandas\core\indexes\base.py", line 4429, in reindex
    raise ValueError("cannot reindex on an axis with duplicate labels")
ValueError: cannot reindex on an axis with duplicate labels
PS C:\Users\W0024618\Desktop\ai-employee-security\src> 
